Workbook

Sheet Correlation Dev Factors
A1: Venter Factors - Correlation of Development Factors
B3: Given the following information:
B5: Accident Year | C5: Age-to-Age Factors
C6: 12-24 Months | D6: 24-36 Months | E6: 36-48 Months | F6: 48-60 Months
B7: 2019 | C7: 2.5 | D7: 1.4 | E7: 1.26 | F7: 1.08
B8: 2020 | C8: 2.1 | D8: 1.2 | E8: 1.34 | F8: 1.05
B9: 2021 | C9: 6.3 | D9: 1.62 | E9: 1.2
B10: 2022 | C10: 4.2 | D10: 1.45
B11: 2023 | C11: 3.6
D13: Degrees of Freedom | E13: t-statistic for 0.95
D14: 1 | E14: =_xlfn.T.INV(0.95,D14) -> 6.3137515
D15: 2 | E15: =_xlfn.T.INV(0.95,D15) -> 2.9199856
D16: 3 | E16: =_xlfn.T.INV(0.95,D16) -> 2.3533634
D17: 4 | E17: =_xlfn.T.INV(0.95,D17) -> 2.1318468
D18: 5 | E18: =_xlfn.T.INV(0.95,D18) -> 2.0150484
B21: Using the Venter correlation test at the 10% t-statistic significance level, test the null hypothesis that the
B22: age-to-age factors from 12-24 months and 24-36 months are independent.
A25: Solution
A26: 1) | B26: Calculate X and Y, the age-to-age factors minus 1 for the column-pair. This is the incremental loss development piece of the age-to-age factor.
C29: X | D29: Y
C30: (12-24mo) | D30: (24-36mo)
C31: =C7-1 -> 1.5 | D31: =D7-1 -> 0.4
C32: =C8-1 -> 1.1 | D32: =D8-1 -> 0.2
C33: =C9-1 -> 5.3 | D33: =D9-1 -> 0.62
C34: =C10-1 -> 3.2 | D34: =D10-1 -> 0.45
B36: Note:
B37: You could skip this step. The sample correlation is the same whether 1 is subtracted or not, but this is what Venter does in the paper.
A40: 2) | B40: Calculate r, the sample correlation coefficient between X and Y.
B42: In Excel
B43: r = CORREL(Array 1, Array 2)
C45: r = | D45: =CORREL(C31:C34,D31:D34) -> 0.91852427
A47: 3) | B47: Calculate T, a t-distributed statistic with n-2 degrees of freedom.
C53: n = | D53: =COUNT(C31:C34) -> 4
C55: T = | D55: =D45*SQRT(($D$53-2)/(1-D45^2)) -> 3.2855483
A57: 4) | B57: Compare the absolute value of T to the corresponding t-statistic to test the significance.
C62: Degrees of Freedom = | D62: =D53-2 -> 2
C64: threshold = t2, 5% = | D64: =E15 -> 2.9199856
B66: Conclusion:
B67: 3.29 > 2.92, so T is significant at the 10% level using a 2-tailed test.
B68: Reject the null hypothesis that the age-to-age factors are independent.
...

Sheet Parameterized BF-Constant
A1: Venter Factors - Parameterized BF: f(d)h(w) – Constant Variance
B3: Given the following information:
C5: Incremental Paid Losses
C6: Accident Year
D7: 12 Months | E7: 24 Months | F7: 36 Months
C8: 2021 | D8: 12080 | E8: 2470 | F8: 860
C9: 2022 | D9: 15830 | E9: 4320
C10: 2023 | D10: 25580
B13: • Assume observations of incremental losses have a constant variance
B14: • Volume-weighted loss development factors are used as the f(d) starting point
B15: • Assume losses are fully developed at 36 months
B18: Calculate the estimated loss reserve for 2023 using the parameterized BF model after 1 iteration of h(w) and f(d).
A21: Solution
A22: 1) | B22: Calculate the initial f(d) values.
B24: • Use the chain ladder method to calculate the LDFs and the cumulative %Paid at each development period. • Set f(d) to the incremental %Paid unless different starting values are specified.
C27: d | D27: 0 | E27: 1 | F27: 2
C28: LDF Age | D28: 12-24 | E28: 24-36 | F28: 36-Ult
C29: LDF | D29: =SUM(D8:E9)/SUM(D8:D9) -> 1.243282 | E29: =SUM(D8:F8)/SUM(D8:E8) -> 1.0591065 | F29: 1
C30: CDF | D30: =D29*E30 -> 1.3167681 | E30: =E29*F30 -> 1.0591065 | F30: =F29 -> 1
C31: % Paid | D31: =1/D30 -> 0.75943519 | E31: =1/E30 -> 0.94419208 | F31: =1/F30 -> 1
C32: f(d) | D32: =D31 -> 0.75943519 | E32: =E31-D31 -> 0.18475689 | F32: =F31-E31 -> 0.055807917
A34: 2) | B34: Calculate row factors, h(w).
C39: AY(w) | D39: h(w)
C40: =C8 -> 2021 | D40: =SUMPRODUCT($D$32:$F$32,$D8:$F8)/SUMSQ($D$32:$F$32) -> 15762.958
C41: =C9 -> 2022 | D41: =SUMPRODUCT($D$32:$E$32,$D9:$E9)/SUMSQ($D$32:$E$32) -> 20986.239
C42: =C10 -> 2023 | D42: =SUMPRODUCT($D$32,$D10)/SUMSQ($D$32) -> 33682.927
A44: 3) | B44: Calculate column factors, f(d). Note that the final f(d)s won’t sum to 1 (see discussion).
C49: d | D49: 12 | E49: 24 | F49: 36
C50: f(d) | D50: =SUMPRODUCT($D$40:$D$42,D$8:D$10)/SUMSQ($D$40:$D$42) -> 0.75913853 | E50: =SUMPRODUCT($D$40:$D$41,E$8:E$9)/SUMSQ($D$40:$D$41) -> 0.18812072 | F50: =SUMPRODUCT($D$40,F$8)/SUMSQ($D$40) -> 0.054558287
A52: 4) | B52: Calculate the expected future incremental losses and sum for the estimated unpaid loss.
C57: AY | D57: 12 | E57: 24 | F57: 36 | H57: h(w)
C58: =C8 -> 2021 | H58: =D40 -> 15762.958
C59: =C9 -> 2022 | F59: =$H59*F$62 -> 1144.9732 | H59: =D41 -> 20986.239
C60: =C10 -> 2023 | E60: =$H60*E$62 -> 6336.4564 | F60: =$H60*F$62 -> 1837.6828 | H60: =D42 -> 33682.927
C62: f(d) | D62: =D50 -> 0.75913853 | E62: =E50 -> 0.18812072 | F62: =F50 -> 0.054558287
E64: Resv(2023) = | F64: =SUM(E60:F60) -> 8174.1392
A66: Discussion
B67: This method is an iterative process. Repeat steps 2 and 3 to calculate the f(d)’s and h(w)’s until convergence. The initial f(d) values can be anything reasonable, but the paper mentions using the f(d)’s from the chain ladder method as a natural starting point. Unless you’re given a specific starting point or are running short of time, I would stick to that. Keep in mind the following points on how to interpret f(d) and h(w): The final f(d) factors won’t necessarily sum to 1. • You can see this if you put a large number for the last incremental. Don’t think of f(d) as the same as % Incremental Emergence. The final h(w) factors aren’t the same as the expected ultimate loss. • Both f(d) and h(w) must be used together to calculate expected incremental loss.
B81: Cape Cod Version of Parameterized BF
B82: A potential twist to this problem is to use only one or two h(w) parameters instead of a separate parameter for each accident year. The Cape Cod version of this method only has one h parameter and step 2 is calculated by summing over the entire triangle as follows:
...

Sheet Parameterized BF-Var ∝ f(d)h(w)
A1: Venter Factors - Parameterized BF: f(d)h(w) – Var ∝ f(d)h(w)
B3: Given the following information:
C5: Incremental Losses
C6: Accident Year
D7: 12 Months | E7: 24 Months | F7: 36 Months
C8: 2021 | D8: 12080 | E8: 2470 | F8: 860
C9: 2022 | D9: 15830 | E9: 4320
C10: 2023 | D10: 25580
B12: • Assume observations of incremental losses have a variance proportional to f(d)h(w)
B13: • The starting column factors, f(d), are:
C15: Development | D15: 0 | E15: 1 | F15: 2
C16: Period(d) | D16: (12 Months) | E16: (24 Months) | F16: (36 Months)
C17: f(d) | D17: 0.75 | E17: 0.2 | F17: 0.05
B19: • Assume losses are fully developed at 36 months
B22: Calculate the estimated ultimate loss for accident year 2023 using the factor times parameter model after 1 iteration.
A26: Solution
A27: 1) | B27: Calculate row factors, h(w). Since the formula calculates h(w)2, make sure to take the square root to get h(w).
C34: (Incremental Losses)^2/f(d)
C35: AY | D35: 12 | E35: 24 | F35: 36
C36: =C8 -> 2021 | D36: =D8^2/D$17 -> 1.9456853e+08 | E36: =E8^2/E$17 -> 30504500 | F36: =F8^2/F$17 -> 14792000
C37: =C9 -> 2022 | D37: =D9^2/D$17 -> 3.3411853e+08 | E37: =E9^2/E$17 -> 93312000
C38: =C10 -> 2023 | D38: =D10^2/D$17 -> 8.7244853e+08
C40: AY | D40: h(w)
C41: =C8 -> 2021 | D41: =SQRT(SUM(D36:F36)/SUM($D$17:$F$17)) -> 15487.577
C42: =C9 -> 2022 | D42: =SQRT(SUM(D37:E37)/SUM($D$17:$E$17)) -> 21211.48
C43: =C10 -> 2023 | D43: =SQRT(SUM(D38)/SUM($D$17)) -> 34106.667
A45: 2) | B45: Calculate column factors, f(d). Since the formula calculates f(d)2, make sure to take the square root to get f(d).
C52: (Incremental Losses)^2/h(w)
C53: AY | D53: 12 | E53: 24 | F53: 36
C54: =C8 -> 2021 | D54: =D8^2/$D41 -> 9422.1583 | E54: =E8^2/$D41 -> 393.92218 | F54: =F8^2/$D41 -> 47.754404
C55: =C9 -> 2022 | D55: =D9^2/$D42 -> 11813.834 | E55: =E9^2/$D42 -> 879.82546
C56: =C10 -> 2023 | D56: =D10^2/$D43 -> 19185
C58: d | D58: 1 | E58: 2 | F58: 3
C59: f(d) | D59: =SQRT(SUM(D54:D56)/SUM($D41:$D43)) -> 0.7555606 | E59: =SQRT(SUM(E54:E55)/SUM($D41:$D42)) -> 0.1863006 | F59: =SQRT(SUM(F54)/SUM($D41)) -> 0.055528377
A61: 3) | B61: Calculate the expected future incremental losses and calculate the unpaid reserve estimate and ultimate loss.
C66: AY | D66: 12 | E66: 24 | F66: 36 | H66: h(w)
C67: =C8 -> 2021 | H67: =D41 -> 15487.577
C68: =C9 -> 2022 | F68: =$H68*F$71 -> 1177.839 | H68: =D42 -> 21211.48
C69: =C10 -> 2023 | E69: =$H69*E$71 -> 6354.0924 | F69: =$H69*F$71 -> 1893.8878 | H69: =D43 -> 34106.667
C71: f(d) | D71: =D59 -> 0.7555606 | E71: =E59 -> 0.1863006 | F71: =F59 -> 0.055528377
...

Sheet Test High Low Diagonals
A1: Venter Factors - Testing for Significantly High/Low Diagonals
B3: Given the following information:
C5: Incremental Losses
C6: Accident Year
D7: 0 | E7: 1 | F7: 2 | G7: 3
C8: 2020 | D8: 410 | E8: 390 | F8: 140 | G8: 60
C9: 2021 | D9: 620 | E9: 480 | F9: 340
C10: 2022 | D10: 570 | E10: 620
C11: 2023 | D11: 610
B14: Set up a table of the data that can be used in a regression model to test for diagonal effects and interpret
B15: the results of the multivariate regression (given below) to test for significantly high or low diagonals.
B17: Given:
D18: CumLoss | E18: CumLoss | F18: CumLoss | G18: Dummy 1 | H18: Dummy 2
D19: Age 0 | E19: Age 1 | F19: Age 2 | G19: Diag. 2 | H19: Diag. 3
C20: b | D20: ='High-Low Diag Regression'!C42 -> 0.92940156 | E20: ='High-Low Diag Regression'!C43 -> 0.25065835 | F20: ='High-Low Diag Regression'!C44 -> -0.018360068 | G20: ='High-Low Diag Regression'!C45 -> -78.377823 | H20: ='High-Low Diag Regression'!C46 -> 77.258464
C21: Std. Dev. (b) | D21: ='High-Low Diag Regression'!D42 -> 0.076136049 | E21: ='High-Low Diag Regression'!D43 -> 0.057235633 | F21: ='High-Low Diag Regression'!D44 -> 0.068504339 | G21: ='High-Low Diag Regression'!D45 -> 49.810464 | H21: ='High-Low Diag Regression'!D46 -> 55.60713
A24: Solution
A25: 1) | B25: Calculate the cumulative loss triangle.
C27: Cumulative Losses
C28: AY | D28: 0 | E28: 1 | F28: 2 | G28: 3
C29: =C8 -> 2020 | D29: =SUM($D8:D8) -> 410 | E29: =SUM($D8:E8) -> 800 | F29: =SUM($D8:F8) -> 940 | G29: =SUM($D8:G8) -> 1000
C30: =C9 -> 2021 | D30: =SUM($D9:D9) -> 620 | E30: =SUM($D9:E9) -> 1100 | F30: =SUM($D9:F9) -> 1440
C31: =C10 -> 2022 | D31: =SUM($D10:D10) -> 570 | E31: =SUM($D10:E10) -> 1190
C32: =C11 -> 2023 | D32: =SUM($D11:D11) -> 610
A34: 2) | B34: Create the table so that the regression model uses incremental losses as the dependent variable. The prior cumulative losses and the diagonal number are the independent variables in the model.
B37: Key points when setting up the table:
B38: • The 1st column shows the incremental losses, excluding the first development period (because there are no prior cumulative losses). • There is a column for each development period (excluding the last one) to show the prior cumulative losses of the incremental losses in column 1. • Include a dummy variable (1 or 0) to indicate which calendar year diagonal the incremental loss is in. But ignore the first two diagonals to avoid over-parameterizing the model.
C45: IncLoss | D45: CumLoss Age 0 | E45: CumLoss Age 1 | F45: CumLoss Age 2 | G45: Dummy 1 (Diagonal 2) | H45: Dummy 2 (Diagonal 3)
C46: =E8 -> 390 | D46: =D29 -> 410 | E46: 0 | F46: 0 | G46: 0 | H46: 0
C47: =E9 -> 480 | D47: =D30 -> 620 | E47: 0 | F47: 0 | G47: 1 | H47: 0
C48: =E10 -> 620 | D48: =D31 -> 570 | E48: 0 | F48: 0 | G48: 0 | H48: 1
C49: =F8 -> 140 | D49: 0 | E49: =E29 -> 800 | F49: 0 | G49: 1 | H49: 0
C50: =F9 -> 340 | D50: 0 | E50: =E30 -> 1100 | F50: 0 | G50: 0 | H50: 1
C51: =G8 -> 60 | D51: 0 | E51: 0 | F51: =F29 -> 940 | G51: 0 | H51: 1
A53: 3) | B53: Run the multivariate regression and test if any of the diagonal dummy variables are significant.
B55: If a coefficient for a diagonal dummy variable is greater than twice the standard deviation of the coefficient, this indicates that the diagonal is significantly high (or low).
C58: Summary of Multivariate Regression Parameters
D59: CumLoss | E59: CumLoss | F59: CumLoss | G59: Dummy 1 | H59: Dummy 2
D60: Age 0 | E60: Age 1 | F60: Age 2 | G60: Diag. 2 | H60: Diag. 3
C61: b | D61: =D20 -> 0.92940156 | E61: =E20 -> 0.25065835 | F61: =F20 -> -0.018360068 | G61: =G20 -> -78.377823 | H61: =H20 -> 77.258464
...

Sheet Goodness of Fit
A1: Venter Factors - Goodness of Fit Test
B3: Given the following information:
B5: Incremental Paid Losses
B6: Accident Year
C7: 12 Months | D7: 24 Months | E7: 36 Months | F7: 48 Months | G7: 60 Months
B8: 2019 | C8: 2820 | D8: 2400 | E8: 1100 | F8: 770 | G8: 430
B9: 2020 | C9: 1890 | D9: 2860 | E9: 1860 | F9: 1090
B10: 2021 | C10: 2480 | D10: 4230 | E10: 1760
B11: 2022 | C11: 2430 | D11: 3950
B12: 2023 | C12: 2250
B14: Below are the final factors from a parameterized BF model:
B16: Age(d) | C16: 12 | D16: 24 | E16: 36 | F16: 48 | G16: 60
B17: f(d) | C17: 0.263 | D17: 0.379 | E17: 0.181 | F17: 0.122 | G17: 0.058
B19: Year(w) | C19: 2019 | D19: 2020 | E19: 2021 | F19: 2022 | G19: 2023
B20: h(w) | C20: 7464 | D20: 7873 | E20: 10482 | F20: 10038 | G20: 8555
B22: Below are the volume-weighted loss development factors for the chain ladder method:
C24: 12-24 | D24: 24-36 | E24: 36-48 | F24: 48-60
B25: LDF | C25: 2.397 | D25: 1.283 | E25: 1.144 | F25: 1.061
B28: Use the adjusted SSE to determine whether the chain ladder method is superior to the alternative loss
B29: emergence pattern used by the parameterized BF model.
A32: Solution
A33: 1) | B33: Calculate the incremental expected losses for all development periods after the first column for the parameterized BF model (the alternative model).
C38: Expected Incremental Losses - Parameterized BF
C39: AY | D39: 12 | E39: 24 | F39: 36 | G39: 48 | H39: 60 | I39: h(w)
C40: =B8 -> 2019 | E40: =E$46*$I40 -> 2828.856 | F40: =F$46*$I40 -> 1350.984 | G40: =G$46*$I40 -> 910.608 | H40: =H$46*$I40 -> 432.912 | I40: =C20 -> 7464
C41: =B9 -> 2020 | E41: =E$46*$I41 -> 2983.867 | F41: =F$46*$I41 -> 1425.013 | G41: =G$46*$I41 -> 960.506 | I41: =D20 -> 7873
C42: =B10 -> 2021 | E42: =E$46*$I42 -> 3972.678 | F42: =F$46*$I42 -> 1897.242 | I42: =E20 -> 10482
C43: =B11 -> 2022 | E43: =E$46*$I43 -> 3804.402 | I43: =F20 -> 10038
C44: =B12 -> 2023 | I44: =G20 -> 8555
C46: f(d) | D46: =C17 -> 0.263 | E46: =D17 -> 0.379 | F46: =E17 -> 0.181 | G46: =F17 -> 0.122 | H46: =G17 -> 0.058
A48: 2) | B48: Calculate the incremental expected losses for all development periods after the first column for the chain ladder method. Use the actual cumulative loss at the prior development period for each calculation.
C53: Expected Incremental Losses – Chain Ladder
C54: AY | D54: 12 | E54: 24 | F54: 36 | G54: 48 | H54: 60
C55: =B8 -> 2019 | E55: =(C$25-1)*SUM($C8:C8) -> 3939.54 | F55: =(D$25-1)*SUM($C8:D8) -> 1477.26 | G55: =(E$25-1)*SUM($C8:E8) -> 910.08 | H55: =(F$25-1)*SUM($C8:F8) -> 432.49
C56: =B9 -> 2020 | E56: =(C$25-1)*SUM($C9:C9) -> 2640.33 | F56: =(D$25-1)*SUM($C9:D9) -> 1344.25 | G56: =(E$25-1)*SUM($C9:E9) -> 951.84
C57: =B10 -> 2021 | E57: =(C$25-1)*SUM($C10:C10) -> 3464.56 | F57: =(D$25-1)*SUM($C10:D10) -> 1898.93
C58: =B11 -> 2022 | E58: =(C$25-1)*SUM($C11:C11) -> 3394.71
C59: =B12 -> 2023
A61: 3) | B61: Calculate the sum of the squared (SSE) error between the actual and fitted incremental losses for each method.
C67: SSE (BF) = | D67: {=SUM((D8:G11-E40:H43)^2)} -> 594263.7
...

Sheet High-Low Diag Regression
B3: Multi-Variate Regression for Testing High-Low Diagonals
B5: The output in this tab corresponds with the regression output given in the "Testing for Significantly High/Low Diagonals". A multi-variate regression couldn't be reasonably tested on the exam, but this is how it would be done: In Step 2 of the recipe, we set up the table for the regression (shown below). In Excel, if you go to Tools -> Data Analysis -> Regression, you can create a multi-variate regression. Simply enter the references for the y variable (IncLoss) and the five x variables and run the regression. Important note: Make sure to check "constant is zero" to set the intercept to zero, because we're testing a chain ladder-like model.
C15: y variable | D15: x variables
C16: IncLoss | D16: CumLoss Age 0 | E16: CumLoss Age 1 | F16: CumLoss Age 2 | G16: Dummy 1 (Diagonal 2) | H16: Dummy 2 (Diagonal 3)
C17: ='Test High Low Diagonals'!C46 -> 390 | D17: ='Test High Low Diagonals'!D46 -> 410 | E17: ='Test High Low Diagonals'!E46 -> 0 | F17: ='Test High Low Diagonals'!F46 -> 0 | G17: ='Test High Low Diagonals'!G46 -> 0 | H17: ='Test High Low Diagonals'!H46 -> 0
C18: ='Test High Low Diagonals'!C47 -> 480 | D18: ='Test High Low Diagonals'!D47 -> 620 | E18: ='Test High Low Diagonals'!E47 -> 0 | F18: ='Test High Low Diagonals'!F47 -> 0 | G18: ='Test High Low Diagonals'!G47 -> 1 | H18: ='Test High Low Diagonals'!H47 -> 0
C19: ='Test High Low Diagonals'!C48 -> 620 | D19: ='Test High Low Diagonals'!D48 -> 570 | E19: ='Test High Low Diagonals'!E48 -> 0 | F19: ='Test High Low Diagonals'!F48 -> 0 | G19: ='Test High Low Diagonals'!G48 -> 0 | H19: ='Test High Low Diagonals'!H48 -> 1
C20: ='Test High Low Diagonals'!C49 -> 140 | D20: ='Test High Low Diagonals'!D49 -> 0 | E20: ='Test High Low Diagonals'!E49 -> 800 | F20: ='Test High Low Diagonals'!F49 -> 0 | G20: ='Test High Low Diagonals'!G49 -> 1 | H20: ='Test High Low Diagonals'!H49 -> 0
C21: ='Test High Low Diagonals'!C50 -> 340 | D21: ='Test High Low Diagonals'!D50 -> 0 | E21: ='Test High Low Diagonals'!E50 -> 1100 | F21: ='Test High Low Diagonals'!F50 -> 0 | G21: ='Test High Low Diagonals'!G50 -> 0 | H21: ='Test High Low Diagonals'!H50 -> 1
C22: ='Test High Low Diagonals'!C51 -> 60 | D22: ='Test High Low Diagonals'!D51 -> 0 | E22: ='Test High Low Diagonals'!E51 -> 0 | F22: ='Test High Low Diagonals'!F51 -> 940 | G22: ='Test High Low Diagonals'!G51 -> 0 | H22: ='Test High Low Diagonals'!H51 -> 1
B25: SUMMARY OUTPUT
B27: Regression Statistics
B28: Multiple R | C28: 0.99941771
B29: R Square | C29: 0.99883577
B30: Adjusted R Square | C30: -0.0058211572
B31: Standard Error | C31: 32.47221
B32: Observations | C32: 6
B34: ANOVA
C35: df | D35: SS | E35: MS | F35: F | G35: Significance F
B36: Regression | C36: 5 | D36: 904645.56 | E36: 180929.11 | F36: 171.58715 | G36: #NUM!
B37: Residual | C37: 1 | D37: 1054.4444 | E37: 1054.4444
B38: Total | C38: 6 | D38: 905700
C40: Coefficients | D40: Standard Error | E40: t Stat | F40: P-value | G40: Lower 95% | H40: Upper 95% | I40: Lower 95.0% | J40: Upper 95.0%
B41: Intercept | C41: 0
B42: CumLoss Age 0 | C42: 0.92940156 | D42: 0.076136049 | E42: 12.207116 | F42: 0.052035339 | G42: -0.037998668 | H42: 1.8968018 | I42: -0.037998668 | J42: 1.8968018
B43: CumLoss Age 1 | C43: 0.25065835 | D43: 0.057235633 | E43: 4.3794108 | F43: 0.14291629 | G43: -0.47658932 | H43: 0.97790602 | I43: -0.47658932 | J43: 0.97790602
B44: CumLoss Age 2 | C44: -0.018360068 | D44: 0.068504339 | E44: -0.26801321 | F44: 0.83329531 | G44: -0.88879022 | H44: 0.85207009 | I44: -0.88879022 | J44: 0.85207009
B45: Dummy 1 (Diagonal 2) | C45: -78.377823 | D45: 49.810464 | E45: -1.5735212 | F45: 0.36040739 | G45: -711.27977 | H45: 554.52413 | I45: -711.27977 | J45: 554.52413
B46: Dummy 2 (Diagonal 3) | C46: 77.258464 | D46: 55.60713 | E46: 1.3893625 | F46: 0.39716249 | G46: -629.29712 | H46: 783.81405 | I46: -629.29712 | J46: 783.81405
